Workbook

Sheet README
A1: Canada's Grocery Oligopoly — consumer-behaviour price analysis
A2: Toronto banner shelf prices (Project Hammer, Feb 2024–Oct 2026) with Statistics Canada context
A4: Question | B4: Do Canada's grocery parents compete banner-against-banner, or manage a portfolio of price tiers?
A5: Unit of analysis | B5: Banner × product × day. Identical products matched on SKU (Loblaws ↔ No Frills share one catalogue) or on UPC/GTIN across owners.
A6: Regular price | B6: The shelf price when no promotion is running; on promotion it is the struck-through 'was' price (or the single-unit price for multi-buy deals).
A7: Persistent change | B7: A regular-price change that is not reversed within 14 days (temporary cuts are excluded).
A8: Synchronisation lift | B8: Share of A's regular-price changes matched by a same-direction change at B within ±k days, divided by the same share when A's dates are shifted ±2–6 months (placebo). 1.0 = chance.
A9: Banner price index | B9: Geometric mean price of an identical basket (UPCs stocked by Loblaws, No Frills, Metro and Walmart in the same month) relative to the four-banner average = 100.
A10: Caveats | B10: Online prices for one Toronto neighbourhood; not a census of stores. No cost or volume data, so margins are not observed. Synchronised or identical prices are consistent with coordination but also with common supplier costs and manufacturer-suggested prices — this is descriptive evidence, not a finding of collusion. Save-On-Foods prices are not Toronto prices (out-of-market control).
A12: Sources | B12: Filipp, J. (2024-2026). Project Hammer: Canadian grocery price data. https://jacobfilipp.com/hammer/ (see also https://projecthammer.org/)
B13: Statistics Canada. Table 18-10-0245-01 Monthly average retail prices for selected products. DOI: https://doi.org/10.25318/1810024501-eng
B14: Statistics Canada. Table 18-10-0004-01 Consumer Price Index, monthly, not seasonally adjusted. DOI: https://doi.org/10.25318/1810000401-eng
A16: Dashboard | B16: Headline KPIs (live formulas referencing the analysis sheets).
A17: Coverage | B17: What the cleaned panel contains, by banner.
A18: Banner_Index | B18: Monthly identical-basket price index; summary via AVERAGEIFS; line chart.
A19: Identical_Gaps | B19: Same item, same day, across banner pairs.
A20: Loblaw_Siblings | B20: Loblaws vs No Frills monthly premium on identical SKUs; by category & brand type.
A21: Synchronisation | B21: Timing of regular-price changes vs placebo, by pair; lift = observed / placebo (formula).
A22: Lead_Lag | B22: Who changes first, and how often rivals land on the identical new price.
A23: Freeze_Test | B23: Weekly increase rates; Nov 1–Feb 5 window vs rest via SUMIFS.
A24: Promotions | B24: Promotion frequency, depth and co-timing.
A25: Brand_Architecture | B25: Private-label share of assortment and of promotion-days.
A26: Inflation | B26: Banner matched-model indices vs StatCan CPI (food purchased from stores).
A27: StatCan_CPI | B27: CPI series, Canada / Ontario, 2018+.
... A29: Cleaning_Log | B29: Row counts at every cleaning step.

Sheet Dashboard
A1: Headline findings
A2: Each figure is a live formula pointing at the analysis sheets
B4: =Identical_Gaps!G5 -> 0.12531328 | C4: Median premium for the identical SKU under the Loblaws banner vs No Frills (same parent, same day).
B6: =Identical_Gaps!M6 -> 0.40362724 | C6: Share of matched item-days on which rival conventional banners Loblaws and Metro charge the identical regular price.
B8: =Identical_Gaps!M8 -> 0.0010666198 | C8: …versus Loblaws and Walmart — conventional and discount tiers almost never share a price point.
B10: =Banner_Index!B5-Banner_Index!B7 -> 23.470701 | C10: Index-point gap between the dearest (Metro) and a discount banner (No Frills) on an identical basket.
B12: =Synchronisation!N5 -> 1.9457164 | C12: Synchronisation lift (±1 day) of regular-price changes inside the Loblaw portfolio.
B14: =Synchronisation!N7 -> 0.88400914 | C14: Same measure across rival owners (Loblaws → Metro): indistinguishable from chance.
B16: =Freeze_Test!D5 -> 0.96842243 | C16: Loblaws' rate of price increases inside vs outside the Nov 1–Feb 5 'freeze' window (≈1 = no freeze).

Sheet Coverage
A1: Panel coverage by banner
A2: Cleaned Project Hammer data; Sobeys (4 days) excluded
A4: banner | B4: parent | C4: role | D4: products | E4: product_days | F4: days | G4: first_day | H4: last_day | I4: promo_share | J4: products_with_gtin
A5: Loblaws | B5: Loblaw | C5: Conventional / premium-leaning | D5: 32155 | E5: 12445186 | F5: 924 | G5: 2024-02-28 | H5: 2026-10-12 | I5: 0.25654811 | J5: 12500
A6: No Frills | B6: Loblaw | C6: Hard discount | D6: 24792 | E6: 9628144 | F6: 924 | G6: 2024-02-28 | H6: 2026-10-12 | I6: 0.13769165 | J6: 12721
A7: T&T | B7: Loblaw | C7: Specialty (Asian) | D7: 13581 | E7: 5535988 | F7: 929 | G7: 2024-02-28 | H7: 2026-10-12 | I7: 0.069239493 | J7: 302
A8: Voilà | B8: Empire (Sobeys) | C8: Online conventional | D8: 26715 | E8: 11508068 | F8: 924 | G8: 2024-02-28 | H8: 2026-10-12 | I8: 0.1920026 | J8: 1288
A9: Metro | B9: Metro Inc. | C9: Conventional | D9: 26380 | E9: 7065868 | F9: 933 | G9: 2024-02-28 | H9: 2026-10-12 | I9: 0.33808967 | J9: 19564
A10: Walmart | B10: Walmart Canada | C10: Mass discount (EDLP) | D10: 37217 | E10: 5459747 | F10: 865 | G10: 2024-03-04 | H10: 2026-10-12 | I10: 0.19396576 | J10: 10943
A11: Galleria | B11: Independent | C11: Specialty (Korean) | D11: 10705 | E11: 6211793 | F11: 930 | G11: 2024-02-28 | H11: 2026-10-12 | I11: 0.0088996848 | J11: 9219
A12: Save-On-Foods | B12: Pattison Food Group | C12: Conventional (Western, out-of-market control) | D12: 15460 | E12: 6595940 | F12: 718 | G12: 2024-09-28 | H12: 2026-10-12 | I12: 0.33363327 | J12: 15180

Sheet Banner_Index
A1: Identical-basket price index by banner (4-banner average = 100)
A2: UPCs stocked by all of Loblaws, No Frills, Metro and Walmart in the month
A4: Banner | B4: Avg regular index (Aug 2024+) | C4: Avg shelf index on regular base | D4: Realised promo discount | I4: month | J4: banner | K4: basket_items | L4: regular_index | M4: shelf_index | N4: shelf_vs_regular_base
A5: Metro | B5: =AVERAGEIFS(L5:L132,J5:J132,A5,I5:I132,">="&DATE(2024,8,1)) -> 113.3393 | C5: =AVERAGEIFS(N5:N132,J5:J132,A5,I5:I132,">="&DATE(2024,8,1)) -> 102.21723 | D5: =1-C5/B5 -> 0.098130764 | I5: 45352 | J5: Loblaws | K5: 32 | L5: 95.781786 | M5: 107.62762 | N5: 109.26303
A6: Loblaws | B6: =AVERAGEIFS(L5:L132,J5:J132,A6,I5:I132,">="&DATE(2024,8,1)) -> 109.70276 | C6: =AVERAGEIFS(N5:N132,J5:J132,A6,I5:I132,">="&DATE(2024,8,1)) -> 99.731596 | D6: =1-C6/B6 -> 0.090892545 | I6: 45352 | J6: Metro | K6: 32 | L6: 129.28894 | M6: 121.07722 | N6: 122.917
A7: No Frills | B7: =AVERAGEIFS(L5:L132,J5:J132,A7,I5:I132,">="&DATE(2024,8,1)) -> 89.8686 | C7: =AVERAGEIFS(N5:N132,J5:J132,A7,I5:I132,">="&DATE(2024,8,1)) -> 85.810314 | D7: =1-C7/B7 -> 0.045158006 | I7: 45352 | J7: No Frills | K7: 32 | L7: 73.340453 | M7: 77.696614 | N7: 78.877223
A8: Walmart | B8: =AVERAGEIFS(L5:L132,J5:J132,A8,I5:I132,">="&DATE(2024,8,1)) -> 89.520587 | C8: =AVERAGEIFS(N5:N132,J5:J132,A8,I5:I132,">="&DATE(2024,8,1)) -> 82.970992 | D8: =1-C8/B8 -> 0.073163011 | I8: 45352 | J8: Walmart | K8: 32 | L8: 110.10629 | M8: 98.766973 | N8: 100.26775
I9: 45383 | J9: Loblaws | K9: 38 | L9: 100.88031 | M9: 102.8485 | N9: 98.148186
A10: Chart data (regular index, pivoted) | I10: 45383 | J10: Metro | K10: 38 | L10: 109.41269 | M10: 109.49858 | N10: 104.49436
A11: month | B11: Metro | C11: Loblaws | D11: No Frills | E11: Walmart | I11: 45383 | J11: No Frills | K11: 38 | L11: 97.417908 | M11: 97.375983 | N11: 92.925775
A12: 45352 | B12: 129.28894 | C12: 95.781786 | D12: 73.340453 | E12: 110.10629 | I12: 45383 | J12: Walmart | K12: 38 | L12: 93.000884 | M12: 91.188841 | N12: 87.021393
A13: 45383 | B13: 109.41269 | C13: 100.88031 | D13: 97.417908 | E13: 93.000884 | I13: 45413 | J13: Loblaws | K13: 44 | L13: 101.4174 | M13: 102.4109 | N13: 98.430369
A14: 45413 | B14: 110.45906 | C14: 101.4174 | D14: 95.846737 | E14: 93.134132 | I14: 45413 | J14: Metro | K14: 44 | L14: 110.45906 | M14: 109.33643 | N14: 105.08671
A15: 45444 | B15: 111.52104 | C15: 105.90349 | D15: 92.829689 | E15: 91.210754 | I15: 45413 | J15: No Frills | K15: 44 | L15: 95.846737 | M15: 96.403383 | N15: 92.656354
A16: 45474 | B16: 111.33384 | C16: 106.64679 | D16: 92.064061 | E16: 91.481838 | I16: 45413 | J16: Walmart | K16: 44 | L16: 93.134132 | M16: 92.639599 | N16: 89.038861
A17: 45505 | B17: 112.35869 | C17: 106.17971 | D17: 91.945805 | E17: 91.16327 | I17: 45444 | J17: Loblaws | K17: 675 | L17: 105.90349 | M17: 110.32455 | N17: 103.95191
A18: 45536 | B18: 112.00652 | C18: 108.43207 | D18: 90.819956 | E18: 90.660406 | I18: 45444 | J18: Metro | K18: 675 | L18: 111.52104 | M18: 107.21176 | N18: 101.01892
A19: 45566 | B19: 111.91696 | C19: 109.26788 | D19: 90.490702 | E19: 90.366536 | I19: 45444 | J19: No Frills | K19: 675 | L19: 92.829689 | M19: 95.586019 | N19: 90.064714
A20: 45597 | B20: 111.75321 | C20: 109.0952 | D20: 90.284704 | E20: 90.849005 | I20: 45444 | J20: Walmart | K20: 675 | L20: 91.210754 | M20: 88.448615 | N20: 83.339586
A21: 45627 | B21: 112.19341 | C21: 109.78096 | D21: 89.529679 | E21: 90.68566 | I21: 45474 | J21: Loblaws | K21: 734 | L21: 106.64679 | M21: 111.04261 | N21: 104.98609
A22: 45658 | B22: 111.7911 | C22: 109.43596 | D22: 90.657731 | E22: 90.162897 | I22: 45474 | J22: Metro | K22: 734 | L22: 111.33384 | M22: 107.36962 | N22: 101.51343
A23: 45689 | B23: 111.89169 | C23: 109.89403 | D23: 89.883958 | E23: 90.478597 | I23: 45474 | J23: No Frills | K23: 734 | L23: 92.064061 | M23: 93.913032 | N23: 88.790796
... A43: 46296 | B43: 114.68359 | C43: 109.43211 | D43: 89.859737 | E43: 88.672474 | I43: 45627 | J43: No Frills | K43: 1884 | L43: 89.529679 | M43: 93.562505 | N43: 85.430289
I44: 45627 | J44: Walmart | K44: 1884 | L44: 90.68566 | M44: 89.854115 | N44: 82.044223
I45: 45658 | J45: Loblaws | K45: 1866 | L45: 109.43596 | M45: 107.46639 | N45: 98.784057
I46: 45658 | J46: Metro | K46: 1866 | L46: 111.7911 | M46: 108.19992 | N46: 99.458326
I47: 45658 | J47: No Frills | K47: 1866 | L47: 90.657731 | M47: 95.035323 | N47: 87.357312
I48: 45658 | J48: Walmart | K48: 1866 | L48: 90.162897 | M48: 90.493077 | N48: 83.182039
I49: 45689 | J49: Loblaws | K49: 1876 | L49: 109.89403 | M49: 107.64133 | N49: 98.754224
I50: 45689 | J50: Metro | K50: 1876 | L50: 111.89169 | M50: 110.16962 | N50: 101.07377
I51: 45689 | J51: No Frills | K51: 1876 | L51: 89.883958 | M51: 93.709783 | N51: 85.972899
I52: 45689 | J52: Walmart | K52: 1876 | L52: 90.478597 | M52: 89.985841 | N52: 82.556413
I53: 45717 | J53: Loblaws | K53: 1963 | L53: 110.18713 | M53: 108.2801 | N53: 99.669625
I54: 45717 | J54: Metro | K54: 1963 | L54: 111.64632 | M54: 109.31817 | N54: 100.62515
I55: 45717 | J55: No Frills | K55: 1963 | L55: 90.664087 | M55: 94.310897 | N55: 86.811257
... I132: 46296 | J132: Walmart | K132: 1554 | L132: 88.672474 | M132: 89.562741 | N132: 82.93472

Sheet Identical_Gaps
A1: Same product, same day: price gaps across banner pairs
A2: Median of each product's daily log price ratio, then summarised across products
A4: banner_a | B4: banner_b | C4: match | D4: group | E4: matched_products | F4: matched_product_days | G4: median_regular_premium_a_vs_b | H4: mean_regular_premium_a_vs_b | I4: median_shelf_premium_a_vs_b | J4: share_items_a_dearer | K4: share_items_identical | L4: share_items_a_cheaper | M4: share_days_identical_regular
A5: Loblaws | B5: No Frills | C5: sku | D5: Same parent (Loblaw) | E5: 16863 | F5: 6211492 | G5: 0.12531328 | H5: 0.15048514 | I5: 0.1002004 | J5: 0.77720453 | K5: 0.16983929 | L5: 0.052956176 | M5: 0.12842695
A6: Loblaws | B6: Metro | C6: gtin | D6: Rival parents, Toronto | E6: 5717 | F6: 1799056 | G6: 0 | H6: -0.013459112 | I6: 0 | J6: 0.17631625 | K6: 0.5191534 | L6: 0.30453035 | M6: 0.40362724
A7: No Frills | B7: Metro | C7: gtin | D7: Rival parents, Toronto | E7: 5300 | F7: 1650369 | G7: -0.16021362 | H7: -0.17261833 | I7: -0.12510425 | J7: 0.048113208 | K7: 0.085849057 | L7: 0.86603774 | M7: 0.066457865
A8: Loblaws | B8: Walmart | C8: gtin | D8: Rival parents, Toronto | E8: 3880 | F8: 1467252 | G8: 0.20523139 | H8: 0.21693641 | I8: 0.17945691 | J8: 0.92293814 | K8: 0.049742268 | L8: 0.027319588 | M8: 0.0010666198
A9: No Frills | B9: Walmart | C9: gtin | D9: Rival parents, Toronto | E9: 3858 | F9: 1476027 | G9: 0.0072202166 | H9: 0.015102653 | I9: 0.020408163 | J9: 0.58216693 | K9: 0.19828927 | L9: 0.21954381 | M9: 0.0050859503
A10: Metro | B10: Walmart | C10: gtin | D10: Rival parents, Toronto | E10: 4472 | F10: 1256365 | G10: 0.22300305 | H10: 0.23555465 | I10: 0.19664269 | J10: 0.92844365 | K10: 0.041815742 | L10: 0.029740608 | M10: 5.0144663e-05
A11: Loblaws | B11: Voilà | C11: gtin | D11: Rival parents, Toronto | E11: 884 | F11: 482330 | G11: 0 | H11: -0.025056871 | I11: -0.027793218 | J11: 0.27262443 | K11: 0.28959276 | L11: 0.43778281 | M11: 0.22273547
A12: Metro | B12: Voilà | C12: gtin | D12: Rival parents, Toronto | E12: 1254 | F12: 542510 | G12: 0 | H12: -0.01323183 | I12: 0 | J12: 0.29904306 | K12: 0.29665072 | L12: 0.40430622 | M12: 0.28332934
A13: Loblaws | B13: Save-On-Foods | C13: gtin | D13: Out-of-market control | E13: 4733 | F13: 1981567 | G13: -0.080064051 | H13: -0.080604145 | I13: -0.07550077 | J13: 0.18106909 | K13: 0.11028946 | L13: 0.70864145 | M13: 0.080655865
A14: No Frills | B14: Save-On-Foods | C14: gtin | D14: Out-of-market control | E14: 4566 | F14: 1842301 | G14: -0.22275754 | H14: -0.23494964 | I14: -0.18283733 | J14: 0.024091108 | K14: 0.024529128 | L14: 0.95137976 | M14: 0.017859188
A15: Metro | B15: Save-On-Foods | C15: gtin | D15: Out-of-market control | E15: 5671 | F15: 1642070 | G15: -0.072239422 | H15: -0.073322847 | I15: -0.055617353 | J15: 0.20983953 | K15: 0.10915183 | L15: 0.68100864 | M15: 0.11179121
A16: Walmart | B16: Save-On-Foods | C16: gtin | D16: Out-of-market control | E16: 3754 | F16: 1315991 | G16: -0.23543124 | H16: -0.24928063 | I16: -0.212 | J16: 0.0090570059 | K16: 0.011454449 | L16: 0.97948855 | M16: 0.00051596098
A17: Metro | B17: Galleria | C17: gtin | D17: Independent specialty | E17: 708 | F17: 267888 | G17: 0 | H17: 0.027012111 | I17: -0.04008016 | J17: 0.4039548 | K17: 0.17372881 | L17: 0.42231638 | M17: 0.1557106

Sheet Loblaw_Siblings
A1: Inside one portfolio: Loblaws vs No Frills on identical SKUs
A2: Median regular-price premium by month, and by category and brand type
A4: month | B4: matched_items | C4: median_premium | D4: share_identical_price
A5: 45323 | B5: 91 | C5: 0.055617353 | D5: 0.18079096
A6: 45352 | B6: 173 | C6: 0.052770449 | D6: 0.17471737
A7: 45383 | B7: 175 | C7: 0.052770449 | D7: 0.15475451
A8: 45413 | B8: 170 | C8: 0.054644809 | D8: 0.20268908
A9: 45444 | B9: 4126 | C9: 0.11119348 | D9: 0.1817515
A10: 45474 | B10: 4268 | C10: 0.11135857 | D10: 0.1922258
A11: 45505 | B11: 4534 | C11: 0.11731844 | D11: 0.18587736
A12: 45536 | B12: 9639 | C12: 0.1305483 | D12: 0.16918754
A13: 45566 | B13: 9669 | C13: 0.14299333 | D13: 0.16436293
A14: 45597 | B14: 10286 | C14: 0.14285714 | D14: 0.15268349
A15: 45627 | B15: 10891 | C15: 0.14319809 | D15: 0.14850809
A16: 45658 | B16: 10215 | C16: 0.14285714 | D16: 0.14060537
... A37: 46296 | B37: 11200 | C37: 0.14 | D37: 0.11733399
A41: category | B41: private_label | C41: products | D41: median_regular_premium
A42: Bakery | B42: FALSE | C42: 660 | D42: 0.11655012
A43: Bakery | B43: TRUE | C43: 208 | D43: 0.10005005
A44: Beverages | B44: FALSE | C44: 2738 | D44: 0.14306152
A45: Beverages | B45: TRUE | C45: 563 | D45: 0.1225
A46: Dairy & eggs | B46: FALSE | C46: 1600 | D46: 0.10888889
A47: Dairy & eggs | B47: TRUE | C47: 503 | D47: 0.090909091
A48: Frozen | B48: FALSE | C48: 362 | D48: 0.13266667
A49: Frozen | B49: TRUE | C49: 101 | D49: 0.071132297
A50: Household & personal care | B50: FALSE | C50: 79 | D50: 0.037064492
A51: Meat & seafood | B51: FALSE | C51: 1138 | D51: 0.12743725
A52: Meat & seafood | B52: TRUE | C52: 351 | D52: 0.10544815
A53: Other | B53: FALSE | C53: 2259 | D53: 0.1225
... A60: Snacks & confectionery | B60: TRUE | C60: 175 | D60: 0.14

Sheet Synchronisation
A1: Do regular-price changes coincide more than chance?
A2: Observed = share of A's persistent changes matched by B (same direction) within ±k days; placebo shifts dates ±2–6 months
A4: banner_a | B4: banner_b | C4: pair_group | D4: events_a | E4: observed_0d | F4: placebo_0d | G4: observed_1d | H4: placebo_1d | I4: observed_3d | J4: placebo_3d | K4: observed_7d | L4: placebo_7d | M4: lift_0d | N4: lift_1d | O4: lift_3d | P4: lift_7d
A5: Loblaws | B5: No Frills | C5: Same parent (Loblaw) | D5: 68517 | E5: 0.066304713 | F5: 0.03104383 | G5: 0.080228265 | H5: 0.041233277 | I5: 0.092750704 | J5: 0.051986076 | K5: 0.16825022 | L5: 0.1284444 | M5: =IFERROR(E5/F5,"") -> 2.1358419 | N5: =IFERROR(G5/H5,"") -> 1.9457164 | O5: =IFERROR(I5/J5,"") -> 1.7841451 | P5: =IFERROR(K5/L5,"") -> 1.309907
A6: No Frills | B6: Loblaws | C6: Same parent (Loblaw) | D6: 67387 | E6: 0.067416564 | F6: 0.032055781 | G6: 0.081588437 | H6: 0.042315872 | I6: 0.094365382 | J6: 0.053114985 | K6: 0.17101221 | L6: 0.13288219 | M6: =IFERROR(E6/F6,"") -> 2.1031016 | N6: =IFERROR(G6/H6,"") -> 1.9280812 | O6: =IFERROR(I6/J6,"") -> 1.7766245 | P6: =IFERROR(K6/L6,"") -> 1.2869461
A7: Loblaws | B7: Metro | C7: Rival parents, Toronto | D7: 23865 | E7: 0.01257071 | F7: 0.013815455 | G7: 0.014791536 | H7: 0.016732334 | I7: 0.022082548 | J7: 0.021498475 | K7: 0.055646344 | L7: 0.05218607 | M7: =IFERROR(E7/F7,"") -> 0.90990201 | N7: =IFERROR(G7/H7,"") -> 0.88400914 | O7: =IFERROR(I7/J7,"") -> 1.0271681 | P7: =IFERROR(K7/L7,"") -> 1.0663065
A8: Metro | B8: Loblaws | C8: Rival parents, Toronto | D8: 9491 | E8: 0.031608893 | F8: 0.032267161 | G8: 0.040248657 | H8: 0.041840445 | I8: 0.059635444 | J8: 0.054441558 | K8: 0.14339901 | L8: 0.13187384 | M8: =IFERROR(E8/F8,"") -> 0.97959942 | N8: =IFERROR(G8/H8,"") -> 0.96195574 | O8: =IFERROR(I8/J8,"") -> 1.095403 | P8: =IFERROR(K8/L8,"") -> 1.0873954
A9: No Frills | B9: Metro | C9: Rival parents, Toronto | D9: 22620 | E9: 0.01357206 | F9: 0.011856022 | G9: 0.015782493 | H9: 0.014806494 | I9: 0.023297966 | J9: 0.020720971 | K9: 0.052166225 | L9: 0.047227843 | M9: =IFERROR(E9/F9,"") -> 1.1447397 | N9: =IFERROR(G9/H9,"") -> 1.065917 | O9: =IFERROR(I9/J9,"") -> 1.1243666 | P9: =IFERROR(K9/L9,"") -> 1.1045651
A10: Metro | B10: No Frills | C10: Rival parents, Toronto | D10: 9067 | E10: 0.033859049 | F10: 0.028076923 | G10: 0.043564575 | H10: 0.039519231 | I10: 0.063857946 | J10: 0.055576923 | K10: 0.14260505 | L10: 0.12203526 | M10: =IFERROR(E10/F10,"") -> 1.2059387 | N10: =IFERROR(G10/H10,"") -> 1.1023639 | O10: =IFERROR(I10/J10,"") -> 1.1490011 | P10: =IFERROR(K10/L10,"") -> 1.1685562
A11: Loblaws | B11: Walmart | C11: Rival parents, Toronto | D11: 20342 | E11: 0.010421787 | F11: 0.010276229 | G11: 0.016419231 | H11: 0.015369922 | I11: 0.023449022 | J11: 0.02264028 | K11: 0.058303018 | L11: 0.052128912 | M11: =IFERROR(E11/F11,"") -> 1.0141646 | N11: =IFERROR(G11/H11,"") -> 1.0682703 | O11: =IFERROR(I11/J11,"") -> 1.0357214 | P11: =IFERROR(K11/L11,"") -> 1.1184392
A12: Walmart | B12: Loblaws | C12: Rival parents, Toronto | D12: 8313 | E12: 0.025502225 | F12: 0.024555941 | G12: 0.040418621 | H12: 0.036214705 | I12: 0.05713942 | J12: 0.05429552 | K12: 0.14314928 | L12: 0.1227797 | M12: =IFERROR(E12/F12,"") -> 1.0385359 | N12: =IFERROR(G12/H12,"") -> 1.1160831 | O12: =IFERROR(I12/J12,"") -> 1.0523782 | P12: =IFERROR(K12/L12,"") -> 1.1659035
A13: No Frills | B13: Walmart | C13: Rival parents, Toronto | D13: 22167 | E13: 0.009563766 | F13: 0.0098864041 | G13: 0.017638832 | H13: 0.015478925 | I13: 0.024901881 | J13: 0.022586523 | K13: 0.055668336 | L13: 0.053642121 | M13: =IFERROR(E13/F13,"") -> 0.96736547 | N13: =IFERROR(G13/H13,"") -> 1.1395386 | O13: =IFERROR(I13/J13,"") -> 1.1025106 | P13: =IFERROR(K13/L13,"") -> 1.0377728
A14: Walmart | B14: No Frills | C14: Rival parents, Toronto | D14: 8468 | E14: 0.025035427 | F14: 0.025239292 | G14: 0.046646197 | H14: 0.039356184 | I14: 0.066603684 | J14: 0.057875693 | K14: 0.14678791 | L14: 0.13703367 | M14: =IFERROR(E14/F14,"") -> 0.99192273 | N14: =IFERROR(G14/H14,"") -> 1.1852317 | O14: =IFERROR(I14/J14,"") -> 1.1508058 | P14: =IFERROR(K14/L14,"") -> 1.0711813
A15: Metro | B15: Walmart | C15: Rival parents, Toronto | D15: 7756 | E15: 0.014311501 | F15: 0.0097150514 | G15: 0.019855596 | H15: 0.014424782 | I15: 0.036745745 | J15: 0.024041304 | K15: 0.077230531 | L15: 0.051156741 | M15: =IFERROR(E15/F15,"") -> 1.4731266 | N15: =IFERROR(G15/H15,"") -> 1.3764919 | O15: =IFERROR(I15/J15,"") -> 1.5284423 | P15: =IFERROR(K15/L15,"") -> 1.5096843
A16: Walmart | B16: Metro | C16: Rival parents, Toronto | D16: 7381 | E16: 0.015038613 | F16: 0.010120294 | G16: 0.019645035 | H16: 0.013856386 | I16: 0.035632028 | J16: 0.022806585 | K16: 0.073025335 | L16: 0.048425504 | M16: =IFERROR(E16/F16,"") -> 1.4859858 | N16: =IFERROR(G16/H16,"") -> 1.4177603 | O16: =IFERROR(I16/J16,"") -> 1.562357 | P16: =IFERROR(K16/L16,"") -> 1.5079933
... A30: Galleria | B30: Metro | C30: Independent specialty | D30: 569 | E30: 0.0035149385 | F30: 0.0038071066 | G30: 0.014059754 | H30: 0.015482234 | I30: 0.026362039 | J30: 0.02893401 | K30: 0.059753954 | L30: 0.056852792 | M30: =IFERROR(E30/F30,"") -> 0.92325718 | N30: =IFERROR(G30/H30,"") -> 0.90812181 | O30: =IFERROR(I30/J30,"") -> 0.91110906 | P30: =IFERROR(K30/L30,"") -> 1.0510294

Sheet Lead_Lag
A1: Who moves first, and do rivals land on the same price?
A2: Nearest same-direction persistent change at the other banner within ±14 days
A4: banner_a | B4: banner_b | C4: pair_group | D4: paired_changes | E4: share_same_day | F4: share_a_first | G4: share_b_first | H4: median_abs_lag_days | I4: share_new_price_identical
A5: Loblaws | B5: No Frills | C5: Same parent (Loblaw) | D5: 18700 | E5: 0.24294118 | F5: 0.38502674 | G5: 0.37203209 | H5: 7 | I5: 0.07631016
A6: Loblaws | B6: Metro | C6: Rival parents, Toronto | D6: 2705 | E6: 0.11090573 | F6: 0.41922366 | G6: 0.46987061 | H6: 7 | I6: 0.28798521
A7: No Frills | B7: Metro | C7: Rival parents, Toronto | D7: 2376 | E7: 0.12920875 | F7: 0.42845118 | G7: 0.44234007 | H7: 7 | I7: 0.036195286
A8: Loblaws | B8: Walmart | C8: Rival parents, Toronto | D8: 2424 | E8: 0.087458746 | F8: 0.44265677 | G8: 0.46988449 | H8: 7 | I8: 0
A9: No Frills | B9: Walmart | C9: Rival parents, Toronto | D9: 2492 | E9: 0.085072231 | F9: 0.46428571 | G9: 0.45064205 | H9: 7 | I9: 0.0096308186
A10: Metro | B10: Walmart | C10: Rival parents, Toronto | D10: 1068 | E10: 0.10393258 | F10: 0.51872659 | G10: 0.37734082 | H10: 7 | I10: 0.0018726592
A11: Loblaws | B11: Voilà | C11: Rival parents, Toronto | D11: 214 | E11: 0.014018692 | F11: 0.45794393 | G11: 0.52803738 | H11: 6 | I11: 0.21495327
A12: Metro | B12: Voilà | C12: Rival parents, Toronto | D12: 155 | E12: 0.025806452 | F12: 0.4516129 | G12: 0.52258065 | H12: 8 | I12: 0.20645161
A13: Loblaws | B13: Save-On-Foods | C13: Out-of-market control | D13: 4682 | E13: 0.15228535 | F13: 0.40068347 | G13: 0.44703118 | H13: 7 | I13: 0.055745408
A14: No Frills | B14: Save-On-Foods | C14: Out-of-market control | D14: 3803 | E14: 0.16671049 | F14: 0.41467263 | G14: 0.41861688 | H14: 7 | I14: 0.025243229
A15: Metro | B15: Save-On-Foods | C15: Out-of-market control | D15: 1941 | E15: 0.16434827 | F15: 0.35497166 | G15: 0.48068006 | H15: 7 | I15: 0.12107161
A16: Walmart | B16: Save-On-Foods | C16: Out-of-market control | D16: 1339 | E16: 0.12322629 | F16: 0.34129948 | G16: 0.53547423 | H16: 7 | I16: 0
A17: Metro | B17: Galleria | C17: Independent specialty | D17: 64 | E17: 0.03125 | F17: 0.46875 | G17: 0.5 | H17: 7 | I17: 0.140625

Sheet Freeze_Test
A1: Is there a Nov 1–Feb 5 price freeze?
A2: Persistent regular-price increases per 1,000 active products per week; window flag on the week midpoint
A4: Banner | B4: Increases /1,000 in window | C4: Increases /1,000 outside | D4: Ratio in / out | E4: Mann-Whitney p (weekly rates) | L4: banner | M4: week | N4: freeze_window | O4: active | P4: ups | Q4: downs | R4: ups_per_1000 | S4: downs_per_1000
A5: Loblaws | B5: =1000*SUMIFS(P5:P905,L5:L905,A5,N5:N905,TRUE)/SUMIFS(O5:O905,L5:L905,A5,N5:N905,TRUE) -> 33.973461 | C5: =1000*SUMIFS(P5:P905,L5:L905,A5,N5:N905,FALSE)/SUMIFS(O5:O905,L5:L905,A5,N5:N905,FALSE) -> 35.081241 | D5: =B5/C5 -> 0.96842243 | E5: 0.93951333 | L5: Galleria | M5: 45488 | N5: FALSE | O5: 4810 | P5: 181 | Q5: 63 | R5: 37.629938 | S5: 13.097713
A6: No Frills | B6: =1000*SUMIFS(P5:P905,L5:L905,A6,N5:N905,TRUE)/SUMIFS(O5:O905,L5:L905,A6,N5:N905,TRUE) -> 28.232002 | C6: =1000*SUMIFS(P5:P905,L5:L905,A6,N5:N905,FALSE)/SUMIFS(O5:O905,L5:L905,A6,N5:N905,FALSE) -> 33.433527 | D6: =B6/C6 -> 0.84442189 | E6: 0.24955941 | L6: Galleria | M6: 45495 | N6: FALSE | O6: 4836 | P6: 111 | Q6: 41 | R6: 22.952854 | S6: 8.4780811
A7: Metro | B7: =1000*SUMIFS(P5:P905,L5:L905,A7,N5:N905,TRUE)/SUMIFS(O5:O905,L5:L905,A7,N5:N905,TRUE) -> 15.898951 | C7: =1000*SUMIFS(P5:P905,L5:L905,A7,N5:N905,FALSE)/SUMIFS(O5:O905,L5:L905,A7,N5:N905,FALSE) -> 14.567545 | D7: =B7/C7 -> 1.0913953 | E7: 0.30176816 | L7: Galleria | M7: 45502 | N7: FALSE | O7: 4857 | P7: 123 | Q7: 112 | R7: 25.324274 | S7: 23.059502
A8: Walmart | B8: =1000*SUMIFS(P5:P905,L5:L905,A8,N5:N905,TRUE)/SUMIFS(O5:O905,L5:L905,A8,N5:N905,TRUE) -> 16.503398 | C8: =1000*SUMIFS(P5:P905,L5:L905,A8,N5:N905,FALSE)/SUMIFS(O5:O905,L5:L905,A8,N5:N905,FALSE) -> 18.328869 | D8: =B8/C8 -> 0.9004046 | E8: 0.17281793 | L8: Galleria | M8: 45509 | N8: FALSE | O8: 4848 | P8: 131 | Q8: 47 | R8: 27.021452 | S8: 9.6947195
A9: Voilà | B9: =1000*SUMIFS(P5:P905,L5:L905,A9,N5:N905,TRUE)/SUMIFS(O5:O905,L5:L905,A9,N5:N905,TRUE) -> 12.692003 | C9: =1000*SUMIFS(P5:P905,L5:L905,A9,N5:N905,FALSE)/SUMIFS(O5:O905,L5:L905,A9,N5:N905,FALSE) -> 7.9876212 | D9: =B9/C9 -> 1.5889591 | E9: 0.40761457 | L9: Galleria | M9: 45516 | N9: FALSE | O9: 5342 | P9: 129 | Q9: 72 | R9: 24.148259 | S9: 13.478098
A10: T&T | B10: =1000*SUMIFS(P5:P905,L5:L905,A10,N5:N905,TRUE)/SUMIFS(O5:O905,L5:L905,A10,N5:N905,TRUE) -> 9.3658393 | C10: =1000*SUMIFS(P5:P905,L5:L905,A10,N5:N905,FALSE)/SUMIFS(O5:O905,L5:L905,A10,N5:N905,FALSE) -> 13.58921 | D10: =B10/C10 -> 0.68921147 | E10: 0.088066651 | L10: Galleria | M10: 45523 | N10: FALSE | O10: 4829 | P10: 95 | Q10: 50 | R10: 19.67281 | S10: 10.354111
A11: Galleria | B11: =1000*SUMIFS(P5:P905,L5:L905,A11,N5:N905,TRUE)/SUMIFS(O5:O905,L5:L905,A11,N5:N905,TRUE) -> 15.756426 | C11: =1000*SUMIFS(P5:P905,L5:L905,A11,N5:N905,FALSE)/SUMIFS(O5:O905,L5:L905,A11,N5:N905,FALSE) -> 15.240628 | D11: =B11/C11 -> 1.0338436 | E11: 0.89240067 | L11: Galleria | M11: 45530 | N11: FALSE | O11: 4866 | P11: 122 | Q11: 49 | R11: 25.071928 | S11: 10.069873
A12: Save-On-Foods | B12: =1000*SUMIFS(P5:P905,L5:L905,A12,N5:N905,TRUE)/SUMIFS(O5:O905,L5:L905,A12,N5:N905,TRUE) -> 18.351977 | C12: =1000*SUMIFS(P5:P905,L5:L905,A12,N5:N905,FALSE)/SUMIFS(O5:O905,L5:L905,A12,N5:N905,FALSE) -> 41.791475 | D12: =B12/C12 -> 0.43913207 | E12: 0.12186172 | L12: Galleria | M12: 45537 | N12: FALSE | O12: 4863 | P12: 142 | Q12: 88 | R12: 29.200082 | S12: 18.095826
L13: Galleria | M13: 45544 | N13: FALSE | O13: 4860 | P13: 109 | Q13: 42 | R13: 22.427984 | S13: 8.6419753
A14: By brand type | L14: Galleria | M14: 45551 | N14: FALSE | O14: 4909 | P14: 145 | Q14: 57 | R14: 29.537584 | S14: 11.611326
A15: banner | B15: brand_type | C15: ups_per_1000_out_window | D15: downs_per_1000_out_window | E15: weeks_out_window | F15: ups_per_1000_in_window | G15: downs_per_1000_in_window | H15: weeks_in_window | I15: increase_rate_ratio_in_vs_out | L15: Galleria | M15: 45558 | N15: FALSE | O15: 5076 | P15: 67 | Q15: 53 | R15: 13.19937 | S15: 10.441292
A16: Galleria | B16: National brand | C16: 15.240628 | D16: 8.6761276 | E16: 88 | F16: 15.756426 | G16: 11.765972 | H16: 27 | I16: 1.0338436 | L16: Galleria | M16: 45565 | N16: FALSE | O16: 4938 | P16: 213 | Q16: 107 | R16: 43.134872 | S16: 21.668692
A17: Loblaws | B17: National brand | C17: 36.046766 | D17: 25.107803 | E17: 88 | F17: 33.75393 | G17: 23.183395 | H17: 27 | I17: 0.93639276 | L17: Galleria | M17: 45572 | N17: FALSE | O17: 4923 | P17: 112 | Q17: 53 | R17: 22.750355 | S17: 10.765793
A18: Loblaws | B18: Private label | C18: 30.852868 | D18: 20.417567 | E18: 88 | F18: 34.91342 | G18: 14.805195 | H18: 27 | I18: 1.1316102 | L18: Galleria | M18: 45579 | N18: FALSE | O18: 4943 | P18: 81 | Q18: 47 | R18: 16.38681 | S18: 9.5083957
A19: Metro | B19: National brand | C19: 14.963176 | D19: 8.5547877 | E19: 88 | F19: 16.639445 | G19: 5.5923447 | H19: 27 | I19: 1.1120263 | L19: Galleria | M19: 45586 | N19: FALSE | O19: 4956 | P19: 110 | Q19: 65 | R19: 22.195319 | S19: 13.115416
A20: Metro | B20: Private label | C20: 12.551754 | D20: 8.7711839 | E20: 88 | F20: 12.208878 | G20: 10.572181 | H20: 27 | I20: 0.97268303 | L20: Galleria | M20: 45593 | N20: FALSE | O20: 4962 | P20: 107 | Q20: 33 | R20: 21.563886 | S20: 6.6505441
A21: No Frills | B21: National brand | C21: 35.353 | D21: 29.050515 | E21: 88 | F21: 28.065046 | G21: 23.170365 | H21: 27 | I21: 0.79385191 | L21: Galleria | M21: 45600 | N21: TRUE | O21: 4964 | P21: 133 | Q21: 171 | R21: 26.792909 | S21: 34.448026
A22: No Frills | B22: Private label | C22: 25.372544 | D22: 15.747065 | E22: 88 | F22: 28.892582 | G22: 14.263095 | H22: 27 | I22: 1.1387341 | L22: Galleria | M22: 45607 | N22: TRUE | O22: 4971 | P22: 108 | Q22: 56 | R22: 21.726011 | S22: 11.265339
A23: Save-On-Foods | B23: National brand | C23: 42.064803 | D23: 23.580937 | E23: 78 | F23: 20.236071 | G23: 2.1438604 | H23: 27 | I23: 0.48106897 | L23: Galleria | M23: 45614 | N23: TRUE | O23: 4977 | P23: 81 | Q23: 62 | R23: 16.274864 | S23: 12.457304
A24: Save-On-Foods | B24: Private label | C24: 40.784974 | D24: 23.493945 | E24: 78 | F24: 11.31005 | G24: 3.5366932 | H24: 27 | I24: 0.27730924 | L24: Galleria | M24: 45621 | N24: TRUE | O24: 4984 | P24: 107 | Q24: 151 | R24: 21.4687 | S24: 30.29695
A25: T&T | B25: National brand | C25: 14.205799 | D25: 12.543398 | E25: 88 | F25: 9.2777593 | G25: 24.308092 | H25: 27 | I25: 0.65309663 | L25: Galleria | M25: 45628 | N25: TRUE | O25: 4959 | P25: 90 | Q25: 79 | R25: 18.14882 | S25: 15.930631
A26: T&T | B26: Private label | C26: 9.5819975 | D26: 7.6946343 | E26: 88 | F26: 9.9488573 | G26: 13.385009 | H26: 27 | I26: 1.0382864 | L26: Galleria | M26: 45635 | N26: TRUE | O26: 4980 | P26: 76 | Q26: 129 | R26: 15.261044 | S26: 25.903614
A27: Voilà | B27: National brand | C27: 8.3549477 | D27: 2.3154589 | E27: 88 | F27: 13.489623 | G27: 2.2604989 | H27: 27 | I27: 1.6145671 | L27: Galleria | M27: 45642 | N27: TRUE | O27: 4981 | P27: 44 | Q27: 69 | R27: 8.8335676 | S27: 13.85264
... A30: Walmart | B30: Private label | C30: 15.259631 | D30: 8.7586476 | E30: 79 | F30: 15.721211 | G30: 6.9959387 | H30: 27 | I30: 1.0302484 | L30: Galleria | M30: 45663 | N30: TRUE | O30: 4884 | P30: 144 | Q30: 50 | R30: 29.484029 | S30: 10.23751
L31: Galleria | M31: 45670 | N31: TRUE | O31: 8556 | P31: 126 | Q31: 175 | R31: 14.726508 | S31: 20.453483
L32: Galleria | M32: 45677 | N32: TRUE | O32: 8571 | P32: 125 | Q32: 57 | R32: 14.584063 | S32: 6.6503325
L33: Galleria | M33: 45684 | N33: TRUE | O33: 8601 | P33: 272 | Q33: 120 | R33: 31.62423 | S33: 13.951866
L34: Galleria | M34: 45691 | N34: FALSE | O34: 8630 | P34: 115 | Q34: 53 | R34: 13.325608 | S34: 6.1413673
L35: Galleria | M35: 45698 | N35: FALSE | O35: 8632 | P35: 156 | Q35: 59 | R35: 18.072289 | S35: 6.8350324
L36: Galleria | M36: 45705 | N36: FALSE | O36: 8648 | P36: 112 | Q36: 59 | R36: 12.950971 | S36: 6.8223867
L37: Galleria | M37: 45712 | N37: FALSE | O37: 8657 | P37: 163 | Q37: 127 | R37: 18.828694 | S37: 14.670209
L38: Galleria | M38: 45719 | N38: FALSE | O38: 8667 | P38: 93 | Q38: 45 | R38: 10.730357 | S38: 5.192108
L39: Galleria | M39: 45726 | N39: FALSE | O39: 8676 | P39: 142 | Q39: 39 | R39: 16.366989 | S39: 4.4951591
L40: Galleria | M40: 45733 | N40: FALSE | O40: 8679 | P40: 112 | Q40: 100 | R40: 12.904713 | S40: 11.522065
L41: Galleria | M41: 45740 | N41: FALSE | O41: 8675 | P41: 152 | Q41: 76 | R41: 17.521614 | S41: 8.7608069
L42: Galleria | M42: 45747 | N42: FALSE | O42: 8668 | P42: 180 | Q42: 67 | R42: 20.766036 | S42: 7.7295801
... L905: Walmart | M905: 46300 | N905: FALSE | O905: 8096 | P905: 119 | Q905: 109 | R905: 14.698617 | S905: 13.463439

Sheet Promotions
A1: Promotion strategy by banner
A2: Share of product-days on promotion, depth, and co-timing across banners
A4: banner | B4: brand_type | C4: product_days | D4: promo_share | E4: median_depth | F4: mean_depth | G4: share_deep_25pct | H4: multibuy_share_of_promos
A5: Save-On-Foods | B5: Private label | C5: 1162957 | D5: 0.28195282 | E5: 0.18012008 | F5: 0.19638906 | G5: 0.27627529 | H5: 0
A6: Walmart | B6: Private label | C6: 826084 | D6: 0.057526837 | E6: 0.1503006 | F6: 0.17853954 | G6: 0.13442227 | H6: 0
A7: Save-On-Foods | B7: National brand | C7: 4188884 | D7: 0.35676256 | E7: 0.22928709 | F7: 0.23834916 | G7: 0.43344252 | H7: 0
A8: Walmart | B8: National brand | C8: 3763826 | D8: 0.23639164 | E8: 0.20030045 | F8: 0.21553387 | G8: 0.29467918 | H8: 0
A9: Loblaws | B9: Private label | C9: 1926019 | D9: 0.24276863 | E9: 0.1638796 | F9: 0.16979527 | G9: 0.12042655 | H9: 0
A10: Metro | B10: National brand | C10: 5273887 | D10: 0.35490939 | E10: 0.16492693 | F10: 0.19282778 | G10: 0.27541504 | H10: 0.21538911
A11: No Frills | B11: National brand | C11: 6251888 | D11: 0.15414799 | E11: 0.15894737 | F11: 0.18142004 | G11: 0.23036526 | H11: 0
A12: T&T | B12: Private label | C12: 572037 | D12: 0.082919462 | E12: 0.19868517 | F12: 0.20531646 | G12: 0.29712223 | H12: 0
A13: Voilà | B13: Private label | C13: 2428918 | D13: 0.11719539 | E13: 0.15015015 | F13: 0.16981466 | G13: 0.20692332 | H13: 0
A14: Loblaws | B14: National brand | C14: 7942081 | D14: 0.28151274 | E14: 0.16527546 | F14: 0.17379756 | G14: 0.12159369 | H14: 0
A15: Metro | B15: Private label | C15: 1077811 | D15: 0.30978251 | E15: 0.12531328 | F15: 0.16143046 | G15: 0.18842735 | H15: 0.20816025
A16: No Frills | B16: Private label | C16: 1631755 | D16: 0.090716437 | E16: 0.13816926 | F16: 0.15973271 | G16: 0.15465235 | H16: 0
... A19: Galleria | B19: National brand | C19: 4308801 | D19: 0.0087307351 | E19: 0.20481928 | F19: 0.22927896 | G19: 0.35878147 | H19: 0
A23: banner_a | B23: banner_b | C23: pair_group | D23: matched_days | E23: p_b_promo | F23: p_b_promo_given_a_promo | G23: promo_cotiming_lift
A24: Loblaws | B24: No Frills | C24: Same parent (Loblaw) | D24: 6317994 | E24: 0.16066824 | F24: 0.22909608 | G24: 1.4258952
A25: Loblaws | B25: Metro | C25: Rival parents, Toronto | D25: 1952799 | E25: 0.42449223 | F25: 0.53950828 | G25: 1.2709497
A26: No Frills | B26: Metro | C26: Rival parents, Toronto | D26: 1772664 | E26: 0.43240682 | F26: 0.49404651 | G26: 1.1425502
A27: Loblaws | B27: Walmart | C27: Rival parents, Toronto | D27: 1510382 | E27: 0.30525059 | F27: 0.42613781 | G27: 1.3960262
A28: No Frills | B28: Walmart | C28: Rival parents, Toronto | D28: 1482418 | E28: 0.30552111 | F28: 0.37757664 | G28: 1.2358447
A29: Metro | B29: Walmart | C29: Rival parents, Toronto | D29: 1375621 | E29: 0.31006433 | F29: 0.38881332 | G29: 1.2539763
A30: Loblaws | B30: Voilà | C30: Rival parents, Toronto | D30: 492272 | E30: 0.26702108 | F30: 0.32637003 | G30: 1.2222632
A31: Metro | B31: Voilà | C31: Rival parents, Toronto | D31: 562743 | E31: 0.25429725 | F31: 0.29928132 | G31: 1.1768956
A32: Loblaws | B32: Save-On-Foods | C32: Out-of-market control | D32: 2054999 | E32: 0.38507026 | F32: 0.45798545 | G32: 1.1893556
A33: No Frills | B33: Save-On-Foods | C33: Out-of-market control | D33: 1910281 | E33: 0.38595997 | F33: 0.43107718 | G33: 1.1168961
A34: Metro | B34: Save-On-Foods | C34: Out-of-market control | D34: 1829757 | E34: 0.40168449 | F34: 0.46473101 | G34: 1.1569553
A35: Walmart | B35: Save-On-Foods | C35: Out-of-market control | D35: 1365625 | E35: 0.4001633 | F35: 0.48042458 | G35: 1.2005713
A36: Metro | B36: Galleria | C36: Independent specialty | D36: 298600 | E36: 0.0071366376 | F36: 0.0084213949 | G36: 1.1800228

Sheet Brand_Architecture
A1: Private label as a steering tool
A2: Store-brand share of assortment and of promotion-days (categorised food & household items)
A4: banner | B4: products | C4: pl_products | D4: promo_days | E4: pl_promo_days | F4: PL share of assortment | G4: PL share of promo-days
A5: Galleria | B5: 7503 | C5: 0 | D5: 37619 | E5: 0 | F5: =C5/B5 -> 0 | G5: =IFERROR(E5/D5,0) -> 0
A6: Loblaws | B6: 25591 | C6: 3883 | D6: 2703374 | E6: 467577 | F6: =C6/B6 -> 0.15173303 | G6: =IFERROR(E6/D6,0) -> 0.17296053
A7: Metro | B7: 23512 | C7: 3116 | D7: 2205639 | E7: 333887 | F7: =C7/B7 -> 0.13252807 | G7: =IFERROR(E7/D7,0) -> 0.15137881
A8: No Frills | B8: 20267 | C8: 3383 | D8: 1111743 | E8: 148027 | F8: =C8/B8 -> 0.1669216 | G8: =IFERROR(E8/D8,0) -> 0.13314858
A9: Save-On-Foods | B9: 12318 | C9: 2531 | D9: 1822336 | E9: 327899 | F9: =C9/B9 -> 0.20547167 | G9: =IFERROR(E9/D9,0) -> 0.17993334
A10: T&T | B10: 10586 | C10: 1378 | D10: 302655 | E10: 47433 | F10: =C10/B10 -> 0.13017193 | G10: =IFERROR(E10/D10,0) -> 0.156723
A11: Voilà | B11: 23031 | C11: 4665 | D11: 2006011 | E11: 284658 | F11: =C11/B11 -> 0.20255308 | G11: =IFERROR(E11/D11,0) -> 0.14190251
A12: Walmart | B12: 30038 | C12: 2406 | D12: 937259 | E12: 47522 | F12: =C12/B12 -> 0.080098542 | G12: =IFERROR(E12/D12,0) -> 0.050703167
A16: banner | B16: category | C16: products | D16: pl_products | E16: promo_days | F16: pl_promo_days
A17: Voilà | B17: Dairy & eggs | C17: 2990 | D17: 562 | E17: 320382 | F17: 46884
A18: Voilà | B18: Frozen | C18: 2055 | D18: 662 | E18: 192631 | F18: 43629
A19: Voilà | B19: Beverages | C19: 5047 | D19: 667 | E19: 510198 | F19: 53536
A20: Voilà | B20: Meat & seafood | C20: 2064 | D20: 556 | E20: 168552 | F20: 33458
A21: Voilà | B21: Household & personal care | C21: 1153 | D21: 65 | E21: 15357 | F21: 699
A22: Galleria | B22: Meat & seafood | C22: 765 | D22: 0 | E22: 1139 | F22: 0
A23: Galleria | B23: Beverages | C23: 1435 | D23: 0 | E23: 2123 | F23: 0
A24: Galleria | B24: Dairy & eggs | C24: 653 | D24: 0 | E24: 2021 | F24: 0
A25: Galleria | B25: Frozen | C25: 305 | D25: 0 | E25: 3889 | F25: 0
A26: Loblaws | B26: Frozen | C26: 797 | D26: 128 | E26: 110453 | F26: 6330
A27: Loblaws | B27: Meat & seafood | C27: 3465 | D27: 610 | E27: 231001 | F27: 46576
A28: Loblaws | B28: Beverages | C28: 5710 | D28: 683 | E28: 726893 | F28: 111862
... A87: T&T | B87: Produce | C87: 1173 | D87: 101 | E87: 33869 | F87: 5190

Sheet Inflation
A1: Banner shelf-price inflation vs official CPI (Aug 2024 = 100)
A2: Chained matched-model index of regular prices vs StatCan CPI, food purchased from stores
A4: month | B4: Loblaws | C4: No Frills | D4: Metro | E4: Walmart | F4: Voilà | G4: T&T | H4: Galleria | I4: Save-On-Foods | J4: CPI food from stores — Ontario | K4: CPI food from stores — Canada
A5: 45505 | B5: 100 | C5: 100 | D5: 100 | E5: 100 | F5: 100 | G5: 100 | H5: 100 | I5: 100 | J5: 100 | K5: 100
A6: 45536 | B6: 101.01124 | C6: 99.88356 | D6: 100.00128 | E6: 99.989974 | F6: 100.11991 | G6: 99.771099 | H6: 100.19307 | J6: 99.895178 | K6: 99.893447
A7: 45566 | B7: 101.112 | C7: 99.559741 | D7: 100.02657 | E7: 100.02892 | F7: 100.27618 | G7: 99.63615 | H7: 100.32914 | I7: 103.11909 | J7: 100.05241 | K7: 99.84017
A8: 45597 | B8: 100.87519 | C8: 99.484145 | D8: 100.10268 | E8: 100.1693 | F8: 100.37432 | G8: 100.67964 | H8: 99.888565 | I8: 103.54262 | J8: 100.62893 | K8: 100.47949
A9: 45627 | B9: 101.49443 | C9: 99.266341 | D9: 100.19719 | E9: 100.08684 | F9: 100.31861 | G9: 100.66167 | H9: 99.202562 | I9: 103.61173 | J9: 100.10482 | K9: 100.15983
A10: 45658 | B10: 101.56839 | C10: 100.95697 | D10: 99.999122 | E10: 100.26569 | F10: 100.44663 | G10: 96.527023 | H10: 99.212619 | I10: 103.75979 | J10: 100.78616 | K10: 100.95898
A11: 45689 | B11: 102.20854 | C11: 101.53376 | D11: 100.38709 | E11: 101.2578 | F11: 100.68097 | G11: 96.248917 | H11: 99.434165 | I11: 104.76687 | J11: 101.31027 | K11: 101.65157
A12: 45717 | B12: 102.48039 | C12: 101.06128 | D12: 100.65338 | E12: 101.0215 | F12: 101.17918 | G12: 96.137928 | H12: 99.709928 | I12: 104.9711 | J12: 101.15304 | K12: 101.75812
A13: 45748 | B13: 102.5096 | C13: 102.28112 | D13: 101.13261 | E13: 100.44995 | F13: 101.42932 | G13: 96.160668 | H13: 99.851426 | I13: 105.22986 | J13: 101.67715 | K13: 102.07778
A14: 45778 | B14: 102.51336 | C14: 102.66892 | D14: 101.3657 | E14: 100.40345 | F14: 101.61995 | G14: 96.289249 | H14: 99.799977 | I14: 105.54023 | J14: 102.35849 | K14: 102.66383
A15: 45809 | B15: 102.84213 | C15: 102.41861 | D15: 101.75672 | E15: 100.96516 | F15: 101.91706 | G15: 96.350642 | H15: 99.677065 | I15: 106.09214 | J15: 102.56813 | K15: 102.7171
A16: 45839 | B16: 102.83244 | C16: 102.50704 | D16: 102.13477 | E16: 101.60138 | F16: 102.40592 | G16: 96.478909 | H16: 99.749606 | I16: 106.28132 | J16: 103.40671 | K16: 103.56953
A17: 45870 | B17: 102.70657 | C17: 102.46707 | D17: 102.2195 | E17: 101.98977 | F17: 102.71295 | G17: 96.533916 | H17: 99.417763 | I17: 106.25146 | J17: 103.19706 | K17: 103.46297
A18: 45901 | B18: 103.13121 | C18: 103.16088 | D18: 101.15382 | E18: 104.29316 | F18: 102.96609 | G18: 96.638202 | H18: 99.765495 | I18: 106.34016 | J18: 103.40671 | K18: 103.88918
... A29: 46235 | B29: 104.21099 | C29: 104.50228 | D29: 104.85095 | E29: 103.32924 | F29: 106.17325 | G29: 97.106868 | H29: 101.37444 | I29: 100.92334 | J29: 106.02725 | K29: 106.3399
A30: 46266 | B30: 104.03122 | C30: 103.92084 | D30: 104.97535 | E30: 103.44853 | F30: 106.29001 | G30: 97.19401 | H30: 101.21801 | I30: 100.89293

Sheet StatCan_CPI
A1: Statistics Canada CPI (Table 18-10-0004-01)
A2: Not seasonally adjusted, 2002 = 100; yoy = 12-month change
A4: month | B4: geo | C4: product | D4: value | E4: yoy | H4: Cumulative change since Jan 2020 (Canada)
A5: 43101 | B5: Ontario | C5: Food purchased from stores | D5: 145.5 | E5: 0.021052632 | H5: product | I5: jan2020 | J5: latest_month | K5: latest | L5: cum_change_since_jan2020
A6: 43101 | B6: Toronto, Ontario | C6: All-items | D6: 135.3 | E6: 0.024224073 | H6: All-items | I6: 136.8 | J6: 2026-08 | K6: 169.8 | L6: 0.24122807
A7: 43101 | B7: Ontario | C7: Fresh fruit and vegetables | D7: 138.1 | E7: 0.05904908 | H7: Bakery and cereal products (excluding baby food) | I7: 156.9 | J7: 2026-08 | K7: 201.9 | L7: 0.28680688
A8: 43101 | B8: Ontario | C8: Bakery and cereal products (excluding baby food) | D8: 156.1 | E8: 0.015614834 | H8: Dairy products and eggs | I8: 138.8 | J8: 2026-08 | K8: 178.4 | L8: 0.28530259
A9: 43101 | B9: Ontario | C9: Meat | D9: 157.9 | E9: 0.014129737 | H9: Food purchased from stores | I9: 151.6 | J9: 2026-08 | K9: 199.6 | L9: 0.31662269
A10: 43101 | B10: Ontario | C10: All-items | D10: 133.2 | E10: 0.018348624 | H10: Fresh fruit and vegetables | I10: 155.5 | J10: 2026-08 | K10: 180.3 | L10: 0.15948553
A11: 43101 | B11: Ontario | C11: Dairy products and eggs | D11: 134.1 | E11: 0.00074626866 | H11: Meat | I11: 169.9 | J11: 2026-08 | K11: 236.8 | L11: 0.39376104
A12: 43101 | B12: Canada | C12: Bakery and cereal products (excluding baby food) | D12: 151 | E12: 0.0039893617
A13: 43101 | B13: Canada | C13: Dairy products and eggs | D13: 134 | E13: -0.0037174721
A14: 43101 | B14: Canada | C14: Fresh fruit and vegetables | D14: 138.2 | E14: 0.060629317
A15: 43101 | B15: Canada | C15: Meat | D15: 156.2 | E15: 0.012313675
A16: 43101 | B16: Canada | C16: Food purchased from stores | D16: 142.6 | E16: 0.016393443
A17: 43101 | B17: Canada | C17: All-items | D17: 131.7 | E17: 0.016988417
A18: 43132 | B18: Ontario | C18: Fresh fruit and vegetables | D18: 134.5 | E18: 0.02126044
A19: 43132 | B19: Ontario | C19: Bakery and cereal products (excluding baby food) | D19: 157.7 | E19: 0.020711974
A20: 43132 | B20: Ontario | C20: Dairy products and eggs | D20: 133 | E20: 0.0022607385
A21: 43132 | B21: Ontario | C21: Meat | D21: 159.4 | E21: 0.013350286
A22: 43132 | B22: Ontario | C22: Food purchased from stores | D22: 144.8 | E22: 0.011879804
A23: 43132 | B23: Ontario | C23: All-items | D23: 134 | E23: 0.021341463
... A1356: 46235 | B1356: Ontario | C1356: Fresh fruit and vegetables | D1356: 180.8 | E1356: 0.022046354

Sheet KVI_Prices
A1: Entry price points on 10 staples vs StatCan average retail price
A2: Median daily lowest shelf price among matching items, Mar–Aug 2026; StatCan Table 18-10-0245-01
A4: kvi | B4: No Frills | C4: Walmart | D4: Loblaws | E4: Metro | F4: Voilà | G4: T&T | H4: Galleria | I4: Save-On-Foods | J4: statcan_ontario_avg | K4: statcan_canada_avg | L4: No Frills vs ON avg | M4: Loblaws vs ON avg | N4: Metro vs ON avg | O4: Walmart vs ON avg
A5: Butter, 454 grams | B5: 4.5 | C5: 5.96 | D5: 5.99 | E5: 5.99 | F5: 5.49 | G5: 8.99 | H5: 7.99 | I5: 4.99 | J5: 5.76 | K5: 5.7783333 | L5: =IFERROR(B5/J5-1,"") -> -0.21875 | M5: =IFERROR(D5/J5-1,"") -> 0.039930556 | N5: =IFERROR(E5/J5-1,"") -> 0.039930556 | O5: =IFERROR(C5/J5-1,"") -> 0.034722222
A6: Canola oil, 3 litres | B6: 9 | D6: 12 | E6: 10.99 | F6: 11.49 | G6: 12.99 | J6: 10.108333 | K6: 10.488333 | L6: =IFERROR(B6/J6-1,"") -> -0.10964551 | M6: =IFERROR(D6/J6-1,"") -> 0.18713932 | N6: =IFERROR(E6/J6-1,"") -> 0.087221764 | O6: =IFERROR(C6/J6-1,"") -> None
A7: Eggs, 1 dozen | B7: 3.79 | C7: 3.93 | D7: 3.85 | E7: 3.99 | F7: 3.99 | G7: 5.29 | I7: 4.15 | J7: 4.99 | K7: 4.8466667 | L7: =IFERROR(B7/J7-1,"") -> -0.24048096 | M7: =IFERROR(D7/J7-1,"") -> -0.22845691 | N7: =IFERROR(E7/J7-1,"") -> -0.2004008 | O7: =IFERROR(C7/J7-1,"") -> -0.21242485
A8: Ketchup, 1 litre | B8: 3.69 | C8: 3.48 | D8: 4.75 | E8: 3.99 | F8: 5.29 | G8: 5.99 | H8: 7.99 | J8: 4.59 | K8: 4.6866667 | L8: =IFERROR(B8/J8-1,"") -> -0.19607843 | M8: =IFERROR(D8/J8-1,"") -> 0.034858388 | N8: =IFERROR(E8/J8-1,"") -> -0.13071895 | O8: =IFERROR(C8/J8-1,"") -> -0.24183007
A9: Milk, 2 litres | B9: 5.49 | C9: 4.57 | D9: 5.48 | E9: 4.79 | F9: 5.59 | G9: 5.68 | H9: 5.29 | J9: 5.8966667 | K9: 5.4966667 | L9: =IFERROR(B9/J9-1,"") -> -0.068965517 | M9: =IFERROR(D9/J9-1,"") -> -0.070661391 | N9: =IFERROR(E9/J9-1,"") -> -0.18767665 | O9: =IFERROR(C9/J9-1,"") -> -0.22498587
A10: Milk, 4 litres | B10: 6.44 | C10: 6.97 | D10: 6.44 | E10: 6.44 | F10: 6 | G10: 6.48 | H10: 7.99 | J10: 6.8966667 | K10: 7 | L10: =IFERROR(B10/J10-1,"") -> -0.066215563 | M10: =IFERROR(D10/J10-1,"") -> -0.066215563 | N10: =IFERROR(E10/J10-1,"") -> -0.066215563 | O10: =IFERROR(C10/J10-1,"") -> 0.010633156
A11: Peanut butter, 1 kilogram | B11: 4.5 | C11: 5.97 | D11: 5.49 | E11: 4.99 | F11: 5.99 | G11: 10.97 | H11: 9.99 | J11: 5.965 | K11: 6.005 | L11: =IFERROR(B11/J11-1,"") -> -0.24559933 | M11: =IFERROR(D11/J11-1,"") -> -0.079631182 | N11: =IFERROR(E11/J11-1,"") -> -0.16345348 | O11: =IFERROR(C11/J11-1,"") -> 0.00083822297
A12: Wheat flour, 2.5 kilograms | B12: 3.79 | C12: 3.77 | D12: 4.5 | E12: 7.49 | F12: 4.49 | G12: 4.49 | H12: 7.99 | J12: 5.2233333 | K12: 5.2716667 | L12: =IFERROR(B12/J12-1,"") -> -0.2744097 | M12: =IFERROR(D12/J12-1,"") -> -0.13848117 | N12: =IFERROR(E12/J12-1,"") -> 0.43395022 | O12: =IFERROR(C12/J12-1,"") -> -0.27823867
A13: White bread, 675 grams | B13: 2.5 | C13: 2.98 | D13: 3.5 | E13: 2.48 | F13: 2.49 | G13: 3.89 | H13: 3.98 | I13: 4.49 | J13: 3.25 | K13: 3.6083333 | L13: =IFERROR(B13/J13-1,"") -> -0.23076923 | M13: =IFERROR(D13/J13-1,"") -> 0.076923077 | N13: =IFERROR(E13/J13-1,"") -> -0.23692308 | O13: =IFERROR(C13/J13-1,"") -> -0.083076923
A14: White sugar, 2 kilograms | B14: 2.99 | C14: 2.97 | D14: 3.49 | E14: 3.49 | F14: 3.49 | G14: 3.99 | H14: 4.49 | J14: 2.7583333 | K14: 2.785 | L14: =IFERROR(B14/J14-1,"") -> 0.083987915 | M14: =IFERROR(D14/J14-1,"") -> 0.2652568 | N14: =IFERROR(E14/J14-1,"") -> 0.2652568 | O14: =IFERROR(C14/J14-1,"") -> 0.07673716
A17: Items matched to each staple (for audit)
A18: kvi | B18: vendor | C18: product_name | D18: units | E18: brand | F18: private_label
A19: Butter, 454 grams | B19: Galleria | C19: GAYLEA BUTTER SALTED | D19: 454G | F19: FALSE
A20: Butter, 454 grams | B20: Galleria | C20: LACTCANTA SALTED BUTTER STICK | D20: 454G | F20: FALSE
A21: Butter, 454 grams | B21: Galleria | C21: GAY LEA SALTED BUTTER STICKS | D21: 454G | F21: FALSE
A22: Butter, 454 grams | B22: Galleria | C22: LACTANTIA BUTTER SALTED | D22: 454G | F22: FALSE
A23: Butter, 454 grams | B23: Galleria | C23: GAYLEA BUTTER SALTED | D23: 454G | F23: FALSE
A24: Butter, 454 grams | B24: Loblaws | C24: Salted Butter , With Sea Salt, Sticks | D24: 454g | E24: Lactantia | F24: FALSE
A25: Butter, 454 grams | B25: Loblaws | C25: Butter | D25: 454g | E25: Kawartha | F25: FALSE
A26: Butter, 454 grams | B26: Loblaws | C26: Salted Butter | D26: 454g | E26: Gay Lea | F26: FALSE
A27: Butter, 454 grams | B27: Loblaws | C27: Salted Butter | D27: 454g | E27: Lactantia | F27: FALSE
A28: Butter, 454 grams | B28: Loblaws | C28: Chef's Signature with 8% Clarified Butter, Salted | D28: 454g | E28: Becel | F28: FALSE
A29: Butter, 454 grams | B29: Loblaws | C29: Salted Butter | D29: 454g | E29: No Name | F29: TRUE
A30: Butter, 454 grams | B30: Loblaws | C30: Butter Sticks, Salted | D30: 454g | E30: Gay Lea | F30: FALSE
A31: Butter, 454 grams | B31: Loblaws | C31: Salted Butter Sticks with Sea Salt - 4 sticks | D31: 454g | E31: Lactantia | F31: FALSE
A32: Butter, 454 grams | B32: Loblaws | C32: Country Churned Salted Butter | D32: 454g | E32: President's Choice | F32: TRUE
A33: Butter, 454 grams | B33: Metro | C33: Salted Butter | D33: 454g | E33: GAY LEA | F33: FALSE
A34: Butter, 454 grams | B34: Metro | C34: Salted Butter Sticks, Country Churned | D34: 454g | E34: LACTANTIA | F34: FALSE
A35: Butter, 454 grams | B35: Metro | C35: Half-Salted Butter | D35: 454g | E35: Selection | F35: TRUE
... A50: Butter, 454 grams | B50: SaveOnFoods | C50: Creamery Salted Butter, 454 Gram | D50: 454g | E50: Fraser Valley | F50: FALSE
A51: Butter, 454 grams | B51: SaveOnFoods | C51: Bake Shop - Country Butter Bread, 454 Gram | D51: 454g | F51: TRUE
A52: Butter, 454 grams | B52: SaveOnFoods | C52: Creamery Butter Salted, 454 Gram | D52: 454g | E52: Dairyland | F52: FALSE
A53: Butter, 454 grams | B53: TandT | C53: Lactantia Salted Butter Sticks | D53: 454g | F53: FALSE
A54: Butter, 454 grams | B54: TandT | C54: Gaylea Butter Quarters | D54: 454g | F54: FALSE
A55: Butter, 454 grams | B55: TandT | C55: Neilson Salted Butter | D55: 454g | F55: FALSE
A56: Butter, 454 grams | B56: TandT | C56: Gaylea Butter Salted | D56: 454g | F56: FALSE
A57: Butter, 454 grams | B57: Voila | C57: Butter Stick Salted 454 g | D57: 454g | E57: Compliments | F57: TRUE
...

Sheet Cleaning_Log
A1: Data cleaning log
A2: Row counts after each step of src/build_panel.py
A4: step | B4: table | C4: rows
A5: 1. raw products loaded | B5: raw_product | C5: 192646
A6: 1. raw price observations loaded | B6: raw_price | C6: 76798210
A7: 2. product dimension (excl. Sobeys) | B7: product_dim | C7: 188245
A8: 3. observations joined to products | B8: obs | C8: 76548620
A9: 3a. drop unparseable date/price | B9: obs | C9: 75943353
A10: 3b. drop prices outside $0.10-$1,000 | B10: obs | C10: 75911849
A11: 3c. cents-scaled prices repaired | B11: obs | C11: 123329
A12: 3d. text-only deals converted to effective unit price | B12: obs | C12: 2831693
A13: 4. collapsed to product-day panel | B13: daily | C13: 64450734
A14: 5. regular-price change events (all) | B14: events | C14: 594899
A15: 5a. persistent regular-price changes | B15: events | C15: 384388
